Workbook
Name Breakdown_Section: Dashboard!$B$70
Name Charts_Section: Dashboard!$B$20
Name KPI_Section: Dashboard!$B$7

Sheet Dashboard
B2: STARBUCKS BEVERAGE NUTRITIONAL DASHBOARD
B3: Nutritional Intelligence for Menu Planning & Consumer Guidance | 242 Beverages | 9 Categories
B5: KPI Overview | C5: Trends & Charts | D5: Breakdown | E5: Task 1 | F5: Task 2 | G5: Task 3 | H5: Task 5
B7: KEY PERFORMANCE INDICATORS
C10: Total Menu Items | E10: Avg Calories / Item | G10: Avg Sugar / Item
C11: =COUNTA('Task 2'!A6:A247) -> 242 | E11: =ROUND(AVERAGE('Task 2'!D6:D247),1) -> 193.9 | G11: =ROUND(AVERAGE('Task 2'!L6:L247),1) -> 33
C12: beverages analysed | E12: kcal per beverage | G12: grams per beverage
C14: Avg Caffeine / Item | E14: Avg Total Fat / Item | G14: Avg Protein / Item
C15: =ROUND(AVERAGE('Task 2'!R6:R247),1) -> 89.5 | E15: =ROUND(AVERAGE('Task 2'!E6:E247),1) -> 2.9 | G15: =ROUND(AVERAGE('Task 2'!M6:M247),1) -> 7
C16: mg per beverage | E16: grams per beverage | G16: grams per beverage
B20: TRENDS & COMPARISONS
B70: DETAILED NUTRITIONAL BREAKDOWN
B73: Category summary table
B75: Category | C75: Avg Calories | D75: Avg Sugar | E75: Avg Caffeine | F75: Avg Fat | H75: Count
B76: Smoothies | C76: 282.22222 | D76: 36.777778 | E76: 5.625 | F76: 0.1 | H76: 9
B77: Frappuccino® Blended Coffee | C77: 276.94444 | D77: 57.083333 | E77: 101.80556 | F77: 3.0027778 | H77: 36
B78: Signature Espresso Drinks | C78: 250 | D78: 38.6 | E78: 73.875 | F78: 5.275 | H78: 40
B79: Signature Espresso Drinks | C79: 250 | D79: 38.6 | E79: 73.875 | F79: 0.1 | H79: 40
B80: Frappuccino® Blended Crème | C80: 233.07692 | D80: 48.461538 | E80: 0 | F80: 1.85 | H80: 13
B81: Tazo® Tea Drinks | C81: 177.30769 | D81: 30.307692 | E81: 50.416667 | F81: 0.1 | H81: 52
B82: Frappuccino® Light Blended Coffee | C82: 162.5 | D82: 32.416667 | E82: 99.583333 | F82: 1.2583333 | H82: 12
B83: Classic Espresso Drinks | C83: 140.17241 | D83: 16.965517 | E83: 73.875 | F83: 3.1275862 | H83: 58
B84: Shaken Iced Beverages | C84: 114.44444 | D84: 26 | E84: 134.61538 | F84: 0.47222222 | H84: 18
B85: Coffee | C85: 4.25 | D85: 0 | E85: 293.75 | F85: 0.1 | H85: 4
B88: Top 10 Highest Calorie Beverages
B90: Beverage Category | C90: Beverage | D90: Calories | E90: Sugar(g) | F90: Fat(g)
B91: Signature Espresso Drinks | C91: White Chocolate Mocha (Without Whipped Cream) | D91: 510 | E91: 74 | F91: 15
B92: Signature Espresso Drinks | C92: White Chocolate Mocha (Without Whipped Cream) | D92: 460 | E92: 64 | F92: 13
B93: Frappuccino® Blended Coffee | C93: Java Chip (Without Whipped Cream) | D93: 460 | E93: 84 | F93: 10
B94: Signature Espresso Drinks | C94: White Chocolate Mocha (Without Whipped Cream) | D94: 450 | E94: 74 | F94: 7
B95: Tazo® Tea Drinks | C95: Tazo® Green Tea Latte | D95: 450 | E95: 71 | F95: 10
B96: Frappuccino® Blended Coffee | C96: Java Chip (Without Whipped Cream) | D96: 430 | E96: 80 | F96: 8
B97: Frappuccino® Blended Coffee | C97: Java Chip (Without Whipped Cream) | D97: 420 | E97: 84 | F97: 5
B98: Signature Espresso Drinks | C98: White Chocolate Mocha (Without Whipped Cream) | D98: 400 | E98: 58 | F98: 11
B99: Tazo® Tea Drinks | C99: Tazo® Green Tea Latte | D99: 390 | E99: 58 | F99: 8
B100: Frappuccino® Blended Coffee | C100: Mocha (Without Whipped Cream) | D100: 390 | E100: 76 | F100: 6

Sheet Task 1
A1: Dashboard | B1: Task 2 | C1: Task 3 | D1: Task 5
A3: Purpose of the Dashboard
A6: Business Scenario | B6: Starbucks Nutritional Intelligence Dashboard This dashboard analyses the official Starbucks beverage menu nutrition dataset (sourced from Kaggle under a Creative Commons licence), comprising 242 menu items across 9 beverage categories. The dashboard is designed to help nutrition-focused decision-makers, including Starbucks menu planners, dietitians, and health-conscious consumers explore caloric content, sugar levels, and caffeine distribution across the full beverage range.
A7: Key Objectives | B7: 1. Identify which beverage categories are highest in calories and sugar to support menu reformulation decisions. 2. Compare average caffeine levels in each drink type to help people who are sensitive to caffeine. 3. Highlight the top 10 highest-calorie beverages to flag items that might need nutritional warnings. 4. Analyse macronutrient composition (fat, protein, carbohydrates) by category to support dietary guidance. 5. Enable quick comparison of preparation methods (Example: nonfat milk vs whole milk) and their caloric impact.
A8: Target Audience | B8: Menu Planners / Product Teams (Primary): Require category-level comparisons of calorie, sugar, and fat averages to guide reformulation, portion decisions, and new product development. Need trend and comparison charts. Dietitians & Nutritionists (Secondary): Need detailed macronutrient breakdowns and the ability to identify outlier items and require accurate tables with clear per-item data for client counselling. Health-Conscious Consumers (Tertiary): Require simple, high-level summaries e.g., which categories are lowest in sugar or calories to support informed ordering decisions at the point of purchase.
A9: KPIs | B9: KPI 1: Average Calories by Category (kcal): Mean caloric content per beverage category. Calories are the primary metric for dietary planning. Category-level averages allow consumers and planners to identify high-energy drink types at a glance. KPI 2: Average Sugar Content by Category (g): Mean grams of sugar per category. Sugar is a leading health concern linked to obesity and diabetes. This KPI supports identification of categories requiring reformulation or consumer warnings. KPI 3: Average Caffeine Content by Category (mg): Mean caffeine per category. Important for consumers with caffeine sensitivity, pregnant individuals, or those managing anxiety disorders. KPI 4: Average Total Fat by Category (g): Mean fat content per category. Fat contributes significantly to caloric density. Comparing fat across categories reveals which beverages may be unsuitable for low-fat diets. KPI 5: Top 10 Highest-Calorie Beverages: Ranked list of the 10 most high-calorie menu items. Identifying outliers helps with focused menu reformulation and ensures compliance with calorie disclosure regulations.

Sheet Task 2
A1: Dashboard | E1: Task 1 | J1: Task 3 | O1: Task 5
A3: DATASET: STARBUCKS BEVERAGE NUTRITIONAL DATA (Kaggle, Creative Commons)
A4: Source: https://www.kaggle.com/datasets/starbucks/starbucks-menu
A5: Beverage_category | B5: Beverage | C5: Beverage_prep | D5: Calories | E5: Total Fat (g) | F5: Trans Fat (g) | G5: Saturated Fat (g) | H5: Sodium (mg) | I5: Total Carbohydrates (g) | J5: Cholesterol (mg) | K5: Dietary Fibre (g) | L5: Sugars (g) | M5: Protein (g) | N5: Vitamin A (% DV) | O5: Vitamin C (% DV) | P5: Calcium (% DV) | Q5: Iron (% DV) | R5: Caffeine (mg)
A6: Classic Espresso Drinks | B6: Caffè Mocha (Without Whipped Cream) | C6: 2% Milk | D6: 340 | E6: 11 | F6: 6 | G6: 0.2 | H6: 30 | I6: 180 | J6: 53 | K6: 2 | L6: 43 | M6: 17 | N6: 0.2 | O6: 0.02 | P6: 0.45 | Q6: 0.3 | R6: 180
A7: Classic Espresso Drinks | B7: Vanilla Latte (Or Other Flavoured Latte) | C7: 2% Milk | D7: 320 | E7: 9 | F7: 4.5 | G7: 0.3 | H7: 35 | I7: 200 | J7: 46 | K7: 0 | L7: 44 | M7: 15 | N7: 0.25 | O7: 0.02 | P7: 0.45 | Q7: 0 | R7: 150 | U7: DATA CLEANING
A8: Classic Espresso Drinks | B8: Caffè Mocha (Without Whipped Cream) | C8: Soymilk | D8: 290 | E8: 9 | F8: 2.5 | G8: 0 | H8: 0 | I8: 140 | J8: 47 | K8: 4 | L8: 33 | M8: 14 | N8: 0.15 | O8: 0 | P8: 0.45 | Q8: 0.5 | R8: 180 | U8: The dataset has 242 rows and 18 columns with no duplicates. It had 1 missing Caffeine value which was filled with the median value (75 mg)
A9: Classic Espresso Drinks | B9: Caffè Mocha (Without Whipped Cream) | C9: Venti Nonfat Milk | D9: 280 | E9: 3 | F9: 2 | G9: 0 | H9: 10 | I9: 160 | J9: 54 | K9: 2 | L9: 44 | M9: 17 | N9: 0.25 | O9: 0 | P9: 0.45 | Q9: 0.3 | R9: 180
A10: Classic Espresso Drinks | B10: Vanilla Latte (Or Other Flavoured Latte) | C10: Soymilk | D10: 270 | E10: 7 | F10: 1 | G10: 0 | H10: 0 | I10: 160 | J10: 39 | K10: 2 | L10: 33 | M10: 12 | N10: 0.15 | O10: 0 | P10: 0.45 | Q10: 0.2 | R10: 150
A11: Classic Espresso Drinks | B11: Caffè Mocha (Without Whipped Cream) | C11: 2% Milk | D11: 260 | E11: 8 | F11: 4.5 | G11: 0.2 | H11: 25 | I11: 140 | J11: 42 | K11: 2 | L11: 34 | M11: 13 | N11: 0.15 | O11: 0.02 | P11: 0.35 | Q11: 0.25 | R11: 175 | U11: 1. Stripped leading/trailing whitespace from all column headers and string values.
A12: Classic Espresso Drinks | B12: Vanilla Latte (Or Other Flavoured Latte) | C12: 2% Milk | D12: 250 | E12: 6 | F12: 3.5 | G12: 0.2 | H12: 25 | I12: 150 | J12: 37 | K12: 0 | L12: 35 | M12: 12 | N12: 0.2 | O12: 0.02 | P12: 0.35 | Q12: 0 | R12: 150 | U12: 2. Converted 'Total Fat (g)' from string to numeric .
A13: Classic Espresso Drinks | B13: Vanilla Latte (Or Other Flavoured Latte) | C13: Venti Nonfat Milk | D13: 250 | E13: 0.3 | F13: 0.2 | G13: 0 | H13: 10 | I13: 180 | J13: 47 | K13: 0 | L13: 45 | M13: 15 | N13: 0.25 | O13: 0 | P13: 0.5 | Q13: 0 | R13: 150 | U13: 3. Converted 'Caffeine (mg)' from string to numeric. 1 missing value filled with column median (75.0 mg).
A14: Classic Espresso Drinks | B14: Caffè Latte | C14: 2% Milk | D14: 240 | E14: 9 | F14: 4.5 | G14: 0.3 | H14: 35 | I14: 220 | J14: 24 | K14: 0 | L14: 22 | M14: 16 | N14: 0.25 | O14: 0.02 | P14: 0.5 | Q14: 0 | R14: 150 | U14: 4. Verified no duplicate rows exist across all 242 records.
A15: Classic Espresso Drinks | B15: Caffè Mocha (Without Whipped Cream) | C15: Soymilk | D15: 230 | E15: 7 | F15: 2 | G15: 0 | H15: 0 | I15: 105 | J15: 37 | K15: 3 | L15: 26 | M15: 11 | N15: 0.1 | O15: 0 | P15: 0.35 | Q15: 0.4 | R15: 175 | U15: 5. All 18 columns were used as they are relevant to nutritional analysis KPIs.
A16: Classic Espresso Drinks | B16: Caffè Mocha (Without Whipped Cream) | C16: Grande Nonfat Milk | D16: 220 | E16: 2.5 | F16: 1.5 | G16: 0 | H16: 5 | I16: 125 | J16: 43 | K16: 2 | L16: 34 | M16: 13 | N16: 0.2 | O16: 0 | P16: 0.35 | Q16: 0.25 | R16: 175
A17: Classic Espresso Drinks | B17: Vanilla Latte (Or Other Flavoured Latte) | C17: Soymilk | D17: 210 | E17: 5 | F17: 0.5 | G17: 0 | H17: 0 | I17: 120 | J17: 31 | K17: 1 | L17: 26 | M17: 9 | N17: 0.1 | O17: 0 | P17: 0.35 | Q17: 0.15 | R17: 150
A18: Classic Espresso Drinks | B18: Caffè Mocha (Without Whipped Cream) | C18: 2% Milk | D18: 200 | E18: 6 | F18: 3.5 | G18: 0.1 | H18: 20 | I18: 115 | J18: 32 | K18: 1 | L18: 26 | M18: 10 | N18: 0.15 | O18: 0 | P18: 0.25 | Q18: 0.2 | R18: 95 | U18: Sub Tables for data visualisations
A19: Classic Espresso Drinks | B19: Vanilla Latte (Or Other Flavoured Latte) | C19: 2% Milk | D19: 200 | E19: 5 | F19: 2.5 | G19: 0.2 | H19: 20 | I19: 125 | J19: 28 | K19: 0 | L19: 27 | M19: 9 | N19: 0.15 | O19: 0 | P19: 0.3 | Q19: 0 | R19: 75
A20: Classic Espresso Drinks | B20: Vanilla Latte (Or Other Flavoured Latte) | C20: Grande Nonfat Milk | D20: 200 | E20: 0.3 | F20: 0.2 | G20: 0 | H20: 5 | I20: 140 | J20: 37 | K20: 0 | L20: 35 | M20: 12 | N20: 0.2 | O20: 0 | P20: 0.35 | Q20: 0 | R20: 150 | U20: 1. Category Averages
A21: Classic Espresso Drinks | B21: Caffè Latte | C21: 2% Milk | D21: 190 | E21: 7 | F21: 3.5 | G21: 0.2 | H21: 30 | I21: 170 | J21: 19 | K21: 0 | L21: 17 | M21: 12 | N21: 0.2 | O21: 0.02 | P21: 0.4 | Q21: 0 | R21: 150
A22: Classic Espresso Drinks | B22: Caffè Latte | C22: Soymilk | D22: 190 | E22: 7 | F22: 1 | G22: 0 | H22: 0 | I22: 170 | J22: 16 | K22: 2 | L22: 11 | M22: 13 | N22: 0.2 | O22: 0 | P22: 0.5 | Q22: 0.25 | R22: 150 | U22: Category | V22: Avg Calories | W22: Avg Sugar | X22: Avg Caffeine | Y22: Avg Fat | Z22: Count
A23: Classic Espresso Drinks | B23: Caffè Mocha (Without Whipped Cream) | C23: Soymilk | D23: 180 | E23: 5 | F23: 1.5 | G23: 0 | H23: 0 | I23: 85 | J23: 28 | K23: 2 | L23: 20 | M23: 9 | N23: 0.1 | O23: 0 | P23: 0.25 | Q23: 0.3 | R23: 95 | U23: Smoothies | V23: =AVERAGEIF($A$6:$A$247, "Smoothies", $D$6:$D$247) -> 282.22222 | W23: =AVERAGEIF($A$6:$A$247, "Smoothies", $L$6:$L$247) -> 36.777778 | X23: =AVERAGEIF($A$6:$A$247, "Smoothies", $R$6:$R$247) -> 5.625 | Y23: =AVERAGEIF($A$6:$A$247, "Coffee", $E$6:$E$247) -> 0.1 | Z23: =COUNTIF($A$6:$A$247, "Smoothies") -> 9
A24: Classic Espresso Drinks | B24: Caffè Latte | C24: Venti Nonfat Milk | D24: 170 | E24: 0.4 | F24: 0.3 | G24: 0 | H24: 10 | I24: 190 | J24: 25 | K24: 0 | L24: 23 | M24: 16 | N24: 0.3 | O24: 0 | P24: 0.5 | Q24: 0 | R24: 150 | U24: Frappuccino® Blended Coffee | V24: =AVERAGEIF($A$6:$A$247, "Frappuccino® Blended Coffee", $D$6:$D$247) -> 276.94444 | W24: =AVERAGEIF($A$6:$A$247, "Frappuccino® Blended Coffee", $L$6:$L$247) -> 57.083333 | X24: =AVERAGEIF($A$6:$A$247, "Frappuccino® Blended Coffee", $R$6:$R$247) -> 101.80556 | Y24: =AVERAGEIF($A$6:$A$247, "Frappuccino® Blended Coffee", $E$6:$E$247) -> 3.0027778 | Z24: =COUNTIF($A$6:$A$247, "Frappuccino® Blended Coffee") -> 36
A25: Classic Espresso Drinks | B25: Caffè Mocha (Without Whipped Cream) | C25: Tall Nonfat Milk | D25: 170 | E25: 2 | F25: 1 | G25: 0 | H25: 5 | I25: 100 | J25: 32 | K25: 1 | L25: 27 | M25: 10 | N25: 0.15 | O25: 0 | P25: 0.25 | Q25: 0.2 | R25: 95 | U25: Signature Espresso Drinks | V25: =AVERAGEIF($A$6:$A$247, "Signature Espresso Drinks", $D$6:$D$247) -> 250 | W25: =AVERAGEIF($A$6:$A$247, "Signature Espresso Drinks", $L$6:$L$247) -> 38.6 | X25: =AVERAGEIF($A$6:$A$247, "Signature Espresso Drinks", $R$6:$R$247) -> 73.875 | Y25: =AVERAGEIF($A$6:$A$247, "Signature Espresso Drinks", $E$6:$E$247) -> 5.275 | Z25: =COUNTIF($A$6:$A$247, "Signature Espresso Drinks") -> 40
A26: Classic Espresso Drinks | B26: Vanilla Latte (Or Other Flavoured Latte) | C26: Soymilk | D26: 160 | E26: 4 | F26: 0.5 | G26: 0 | H26: 0 | I26: 95 | J26: 23 | K26: 1 | L26: 20 | M26: 7 | N26: 0.1 | O26: 0 | P26: 0.3 | Q26: 0.15 | R26: 75 | U26: Signature Espresso Drinks | V26: =AVERAGEIF($A$6:$A$247, "Signature Espresso Drinks", $D$6:$D$247) -> 250 | W26: =AVERAGEIF($A$6:$A$247, "Signature Espresso Drinks", $L$6:$L$247) -> 38.6 | X26: =AVERAGEIF($A$6:$A$247, "Signature Espresso Drinks", $R$6:$R$247) -> 73.875 | Y26: =AVERAGEIF($A$6:$A$247, "Coffee", $E$6:$E$247) -> 0.1 | Z26: =COUNTIF($A$6:$A$247, "Signature Espresso Drinks") -> 40
A27: Classic Espresso Drinks | B27: Skinny Latte (Any Flavour) | C27: Venti Nonfat Milk | D27: 160 | E27: 0.3 | F27: 0.2 | G27: 0 | H27: 10 | I27: 200 | J27: 24 | K27: 0 | L27: 21 | M27: 15 | N27: 0.25 | O27: 0 | P27: 0.5 | Q27: 0 | R27: 150 | U27: Frappuccino® Blended Crème | V27: =AVERAGEIF($A$6:$A$247, "Frappuccino® Blended Crème", $D$6:$D$247) -> 233.07692 | W27: =AVERAGEIF($A$6:$A$247, "Frappuccino® Blended Crème", $L$6:$L$247) -> 48.461538 | X27: =AVERAGEIF($A$6:$A$247, "Frappuccino® Blended Crème", $R$6:$R$247) -> 0 | Y27: =AVERAGEIF($A$6:$A$247, "Frappuccino® Blended Crème", $E$6:$E$247) -> 1.85 | Z27: =COUNTIF($A$6:$A$247, "Frappuccino® Blended Crème") -> 13
A28: Classic Espresso Drinks | B28: Caffè Latte | C28: 2% Milk | D28: 150 | E28: 6 | F28: 3 | G28: 0.2 | H28: 25 | I28: 135 | J28: 15 | K28: 0 | L28: 14 | M28: 10 | N28: 0.15 | O28: 0 | P28: 0.3 | Q28: 0 | R28: 75 | U28: Tazo® Tea Drinks | V28: =AVERAGEIF($A$6:$A$247, "Tazo® Tea Drinks", $D$6:$D$247) -> 177.30769 | W28: =AVERAGEIF($A$6:$A$247, "Tazo® Tea Drinks", $L$6:$L$247) -> 30.307692 | X28: =AVERAGEIF($A$6:$A$247, "Tazo® Tea Drinks", $R$6:$R$247) -> 50.416667 | Y28: =AVERAGEIF($A$6:$A$247, "Coffee", $E$6:$E$247) -> 0.1 | Z28: =COUNTIF($A$6:$A$247, "Tazo® Tea Drinks") -> 52
A29: Classic Espresso Drinks | B29: Caffè Latte | C29: Soymilk | D29: 150 | E29: 5 | F29: 0.5 | G29: 0 | H29: 0 | I29: 130 | J29: 13 | K29: 1 | L29: 8 | M29: 10 | N29: 0.15 | O29: 0 | P29: 0.4 | Q29: 0.15 | R29: 150 | U29: Frappuccino® Light Blended Coffee | V29: =AVERAGEIF($A$6:$A$247, "Frappuccino® Light Blended Coffee", $D$6:$D$247) -> 162.5 | W29: =AVERAGEIF($A$6:$A$247, "Frappuccino® Light Blended Coffee", $L$6:$L$247) -> 32.416667 | X29: =AVERAGEIF($A$6:$A$247, "Frappuccino® Light Blended Coffee", $R$6:$R$247) -> 99.583333 | Y29: =AVERAGEIF($A$6:$A$247, "Frappuccino® Light Blended Coffee", $E$6:$E$247) -> 1.2583333 | Z29: =COUNTIF($A$6:$A$247, "Frappuccino® Light Blended Coffee") -> 12
A30: Classic Espresso Drinks | B30: Vanilla Latte (Or Other Flavoured Latte) | C30: Tall Nonfat Milk | D30: 150 | E30: 0.2 | F30: 0.1 | G30: 0 | H30: 5 | I30: 110 | J30: 28 | K30: 0 | L30: 27 | M30: 9 | N30: 0.15 | O30: 0 | P30: 0.3 | Q30: 0 | R30: 75 | U30: Classic Espresso Drinks | V30: =AVERAGEIF($A$6:$A$247, "Classic Espresso Drinks", $D$6:$D$247) -> 140.17241 | W30: =AVERAGEIF($A$6:$A$247, "Classic Espresso Drinks", $L$6:$L$247) -> 16.965517 | X30: =AVERAGEIF($A$6:$A$247, "Signature Espresso Drinks", $R$6:$R$247) -> 73.875 | Y30: =AVERAGEIF($A$6:$A$247, "Classic Espresso Drinks", $E$6:$E$247) -> 3.1275862 | Z30: =COUNTIF($A$6:$A$247, "Classic Espresso Drinks") -> 58
A31: Classic Espresso Drinks | B31: Cappuccino | C31: 2% Milk | D31: 150 | E31: 6 | F31: 3 | G31: 0.2 | H31: 25 | I31: 135 | J31: 16 | K31: 0 | L31: 14 | M31: 10 | N31: 0.15 | O31: 0 | P31: 0.3 | Q31: 0 | R31: 150 | U31: Shaken Iced Beverages | V31: =AVERAGEIF($A$6:$A$247, "Shaken Iced Beverages", $D$6:$D$247) -> 114.44444 | W31: =AVERAGEIF($A$6:$A$247, "Shaken Iced Beverages", $L$6:$L$247) -> 26 | X31: =AVERAGEIF($A$6:$A$247, "Shaken Iced Beverages", $R$6:$R$247) -> 134.61538 | Y31: =AVERAGEIF($A$6:$A$247, "Shaken Iced Beverages", $E$6:$E$247) -> 0.47222222 | Z31: =COUNTIF($A$6:$A$247, "Shaken Iced Beverages") -> 18
A32: Classic Espresso Drinks | B32: Caffè Latte | C32: Grande Nonfat Milk | D32: 130 | E32: 0.3 | F32: 0.2 | G32: 0 | H32: 5 | I32: 150 | J32: 19 | K32: 0 | L32: 18 | M32: 13 | N32: 0.2 | O32: 0 | P32: 0.4 | Q32: 0 | R32: 150 | U32: Coffee | V32: =AVERAGEIF($A$6:$A$247, "Coffee", $D$6:$D$247) -> 4.25 | W32: =AVERAGEIF($A$6:$A$247, "Coffee", $L$6:$L$247) -> 0 | X32: =AVERAGEIF($A$6:$A$247, "Coffee", $R$6:$R$247) -> 293.75 | Y32: =AVERAGEIF($A$6:$A$247, "Coffee", $E$6:$E$247) -> 0.1 | Z32: =COUNTIF($A$6:$A$247, "Coffee") -> 4
A33: Classic Espresso Drinks | B33: Caffè Mocha (Without Whipped Cream) | C33: 2% Milk | D33: 130 | E33: 4 | F33: 2 | G33: 0.1 | H33: 10 | I33: 70 | J33: 21 | K33: 1 | L33: 17 | M33: 6 | N33: 0.08 | O33: 0 | P33: 0.15 | Q33: 0.1 | R33: 85
A34: Classic Espresso Drinks | B34: Vanilla Latte (Or Other Flavoured Latte) | C34: 2% Milk | D34: 130 | E34: 3.5 | F34: 1.5 | G34: 0.1 | H34: 15 | I34: 80 | J34: 18 | K34: 0 | L34: 17 | M34: 6 | N34: 0.1 | O34: 0 | P34: 0.2 | Q34: 0 | R34: 75 | U34: 2. Top 10 Calories:
A35: Classic Espresso Drinks | B35: Cappuccino | C35: 2% Milk | D35: 120 | E35: 4 | F35: 2 | G35: 0.1 | H35: 15 | I35: 100 | J35: 12 | K35: 0 | L35: 10 | M35: 8 | N35: 0.1 | O35: 0 | P35: 0.25 | Q35: 0 | R35: 150
A36: Classic Espresso Drinks | B36: Cappuccino | C36: Soymilk | D36: 120 | E36: 4.5 | F36: 0.5 | G36: 0 | H36: 0 | I36: 110 | J36: 11 | K36: 1 | L36: 7 | M36: 9 | N36: 0.1 | O36: 0 | P36: 0.35 | Q36: 0.15 | R36: 150 | U36: Beverage Category | V36: Beverage | W36: Calories | X36: Sugar(g) | Y36: Fat(g)
A37: Classic Espresso Drinks | B37: Skinny Latte (Any Flavour) | C37: Grande Nonfat Milk | D37: 120 | E37: 0.3 | F37: 0.2 | G37: 0 | H37: 5 | I37: 160 | J37: 18 | K37: 0 | L37: 16 | M37: 12 | N37: 0.2 | O37: 0 | P37: 0.35 | Q37: 0 | R37: 150 | U37: Signature Espresso Drinks | V37: White Chocolate Mocha (Without Whipped Cream) | W37: 510 | X37: 74 | Y37: 15
A38: Classic Espresso Drinks | B38: Caffè Latte | C38: Soymilk | D38: 110 | E38: 4.5 | F38: 0.5 | G38: 0 | H38: 0 | I38: 105 | J38: 10 | K38: 1 | L38: 6 | M38: 8 | N38: 0.1 | O38: 0 | P38: 0.3 | Q38: 0.15 | R38: 75 | U38: Signature Espresso Drinks | V38: White Chocolate Mocha (Without Whipped Cream) | W38: 460 | X38: 64 | Y38: 13
A39: Classic Espresso Drinks | B39: Caffè Mocha (Without Whipped Cream) | C39: Short Nonfat Milk | D39: 110 | E39: 1.5 | F39: 1 | G39: 0 | H39: 5 | I39: 60 | J39: 21 | K39: 1 | L39: 17 | M39: 7 | N39: 0.08 | O39: 0 | P39: 0.15 | Q39: 0.1 | R39: 85 | U39: Frappuccino® Blended Coffee | V39: Java Chip (Without Whipped Cream) | W39: 460 | X39: 84 | Y39: 10
A40: Classic Espresso Drinks | B40: Caffè Mocha (Without Whipped Cream) | C40: Soymilk | D40: 110 | E40: 3.5 | F40: 1 | G40: 0 | H40: 0 | I40: 55 | J40: 19 | K40: 2 | L40: 13 | M40: 6 | N40: 0.06 | O40: 0 | P40: 0.15 | Q40: 0.2 | R40: 85 | U40: Signature Espresso Drinks | V40: White Chocolate Mocha (Without Whipped Cream) | W40: 450 | X40: 74 | Y40: 7
A41: Classic Espresso Drinks | B41: Vanilla Latte (Or Other Flavoured Latte) | C41: Soymilk | D41: 110 | E41: 2.5 | F41: 0.3 | G41: 0 | H41: 0 | I41: 60 | J41: 16 | K41: 1 | L41: 13 | M41: 5 | N41: 0.06 | O41: 0 | P41: 0.2 | Q41: 0.08 | R41: 75 | U41: Tazo® Tea Drinks | V41: Tazo® Green Tea Latte | W41: 450 | X41: 71 | Y41: 10
...

Sheet Task 3
A1: Dashboard | B1: Task 1 | C1: Task 2 | D1: Task 5
A3: Visualisations
C5: A horizontal bar chart was chosen to compare average calories across 9 drink categories. Bar charts clearly show differences between categories because bar length directly represents the value. The horizontal layout works better here because the category names are long and would overlap on a vertical chart. The bars are sorted from lowest to highest calories so it’s easy to see which categories are the most energy-dense. This directly supports KPI 1: Average Calories per Item.
A27: Average kilocalorie content per beverage, grouped by the 9 Starbucks beverage categories, sorted from lowest to highest.
C29: A column bar chart was used to compare caffeine content across drink categories, following the same approach as Chart 2. Caffeine is a separately measured value that differs clearly between categories. Coffee is expected to be highest, while Smoothies are lowest. Showing this in a bar chart gives quick, useful insight for people who are sensitive to caffeine. This chart directly supports KPI 3: Average Caffeine per Item.
A51: Average milligrams of caffeine per beverage across all 9 Starbucks beverage categories.
C54: A pie chart was chosen because this data shows how each category makes up part of the whole menu. Each slice shows that category's share of the total. Pie charts work best for composition or proportion data where values add up to a meaningful whole (100% of the menu). Category names and percentages are shown directly on each slice, so there’s no need to look at a separate legend.
A73: Proportional share of the total 242 Starbucks menu items contributed by each of the 9 beverage categories.
C75: A vertical column chart was used to compare average sugar content across categories. Chart 1 used horizontal bars because the labels were long, but this chart uses columns to create a clear visual difference between the two charts. Both charts compare one measure across groups, but changing the orientation stops the dashboard from looking repetitive. The Y-axis starts at zero so the differences between categories are not exaggerated. This chart supports KPI 2: Average Sugar per Item by highlighting categories that may pose health risks due to high sugar levels.
A96: Average grams of sugar per beverage across all 9 Starbucks beverage categories.
C99: A horizontal bar chart was used because the data shows individual beverage names, which are long and easier to read horizontally. Unlike Charts 1-4 that show category averages, this chart focuses on specific products to find outliers. Sorting the bars from highest to lowest makes the highest-calorie drinks easy to spot.This chart supports KPI 5: Top 10 Highest-Calorie Beverages, and is important for meeting calorie disclosure rules.
A120: The 10 Starbucks menu items with the highest total calorie counts, ranked from lowest to highest.

Sheet Task 5
A1: Dashboard | B1: Task1 | C1: Task 2 | D1: Task 3
A3: ETHICAL CONSIDERATIONS IN DASHBOARD DESIGN
A5: Data privacy
A6: Protecting user and customer data is a basic duty in any data system. The Starbucks nutrition data in this dashboard has no personal details, only combined nutrition numbers for public menu items, so it already uses minimal data.
A7: Transparency
A8: Transparency means dashboard users can easily see where data comes from, how it was changed, and what its limits are. In this dashboard, the data source is explicitly cited in the Task 2 header (Kaggle, Creative Commons licence, full URL provided) and a data cleaning summary documents every modification made to the raw dataset, including the handling of the single missing Caffeine value.
A9: Avoiding misleading visualisations
A10: Visualisations can strongly affect how people understand data, so all charts are designed in a way they show information honestly. All 9 drink categories are shown, axes start at zero when suitable, bar charts are sorted by real values, and the pie chart is only used for a true part-to-whole relationship.
